----------------------------------------------------------------------
Ran 2 tests in 40.788s

OK
----------------------------------------------------------------------
Ran 1 test in 0.018s

OK
----------------------------------------------------------------------
Ran 2 tests in 0.502s

OK
----------------------------------------------------------------------
Ran 1 test in 0.000s

OK
----------------------------------------------------------------------
Ran 6 tests in 5.468s

OK
----------------------------------------------------------------------
Ran 3 tests in 0.020s

OK
----------------------------------------------------------------------
Ran 2 tests in 0.427s

OK
----------------------------------------------------------------------
Ran 2 tests in 0.016s

OK
----------------------------------------------------------------------
Ran 2 tests in 0.147s

OK
----------------------------------------------------------------------
Ran 9 tests in 0.053s

OK
----------------------------------------------------------------------
Ran 32 tests in 4.665s

OK
----------------------------------------------------------------------
Ran 3 tests in 13.911s

OK
======================================================================
ERROR: test_run_notebook (test_run_notebooks.TestRunNotebooksPython)
----------------------------------------------------------------------
Traceback (most recent call last):
  File "C:\xavierdupre\__home_\GitHub\pandas_streaming\_unittests\ut_documentation\test_run_notebooks.py", line 51, in test_run_notebook
    res, fLOG=fLOG, dump=pandas_streaming)
  File "C:\xavierdupre\__home_\GitHub\pyquickhelper\src\pyquickhelper\ipythonhelper\run_notebook.py", line 380, in execute_notebook_list_finalize_ut
    raise fails[0][1]["error"]
  File "C:\xavierdupre\__home_\GitHub\pyquickhelper\src\pyquickhelper\ipythonhelper\run_notebook.py", line 266, in execute_notebook_list
    detailed_log=detailed_log, startup_timeout=startup_timeout)
  File "C:\xavierdupre\__home_\GitHub\pyquickhelper\src\pyquickhelper\ipythonhelper\run_notebook.py", line 174, in run_notebook
    valid=valid, clean_function=clean_function)
  File "C:\xavierdupre\__home_\GitHub\pyquickhelper\src\pyquickhelper\ipythonhelper\notebook_runner.py", line 975, in run_notebook
    self.run_cell(i, cell, clean_function=clean_function)
  File "C:\xavierdupre\__home_\GitHub\pyquickhelper\src\pyquickhelper\ipythonhelper\notebook_runner.py", line 501, in run_cell
    self._filename))
pyquickhelper.ipythonhelper.notebook_runner.NotebookError: FILENAME
C:\xavierdupre\__home_\GitHub\pandas_streaming\_doc\notebooks\first_steps.ipynb:1:1

CELL status=error, reason=None -- 2 length=91 -- :
-----------------
from pandas_streaming.df import StreamingDataFrame
sdf = StreamingDataFrame.read_df(df)
sdf
-----------------
TRACE:
---------------------------------------------------------------------------
ModuleNotFoundError                       Traceback (most recent call last)
<ipython-input-5-5410ade1db0d> in <module>
----> 1 from pandas_streaming.df import StreamingDataFrame
      2 sdf = StreamingDataFrame.read_df(df)
      3 sdf

ModuleNotFoundError: No module named 'pandas_streaming'
RAW:
REPLY:
reply['buffers']=[]
reply['content']=dict
    [ename]=ModuleNotFoundError
    [engine_info]={'engine_uuid': 'a8d5dfe5-804a-4254-bf44-310afd898721', 'engine_id': -1, 'method': 'execute'}
    [evalue]=No module named 'pandas_streaming'
    [execution_count]=5
    [payload]=[]
    [status]=error
    [traceback]=['\x1b[1;31m---------------------------------------------------------------------------\x1b[0m', '\x1b[1;31mModuleNotFoundError\x1b[0m                       Traceback (most recent call last)', '\x1b[1;32m<ipython-input-5-5410ade1db0d>\x1b[0m in \x1b[0;36m<module>\x1b[1;34m\x1b[0m\n\x1b[1;32m----> 1\x1b[1;33m \x1b[1;32mfrom\x1b[0m \x1b[0mpandas_streaming\x1b[0m\x1b[1;33m.\x1b[0m\x1b[0mdf\x1b[0m \x1b[1;32mimport\x1b[0m \x1b[0mStreamingDataFrame\x1b[0m\x1b[1;33m\x1b[0m\x1b[1;33m\x1b[0m\x1b[0m\n\x1b[0m\x1b[0;32m      2\x1b[0m \x1b[0msdf\x1b[0m \x1b[1;33m=\x1b[0m \x1b[0mStreamingDataFrame\x1b[0m\x1b[1;33m.\x1b[0m\x1b[0mread_df\x1b[0m\x1b[1;33m(\x1b[0m\x1b[0mdf\x1b[0m\x1b[1;33m)\x1b[0m\x1b[1;33m\x1b[0m\x1b[1;33m\x1b[0m\x1b[0m\n\x1b[0;32m      3\x1b[0m \x1b[0msdf\x1b[0m\x1b[1;33m\x1b[0m\x1b[1;33m\x1b[0m\x1b[0m\n', "\x1b[1;31mModuleNotFoundError\x1b[0m: No module named 'pandas_streaming'"]
    [user_expressions]={}
reply['header']=dict
    [date]=2019-05-24 11:14:23.119458+00:00
    [msg_id]=5c70e62f-47e6890f3d58a8363d91b19f
    [msg_type]=execute_reply
    [session]=9a3bca99-b1fcb59e885203a11e447365
    [username]=username
    [version]=5.3
reply['metadata']=dict
    [dependencies_met]=True
    [engine]=a8d5dfe5-804a-4254-bf44-310afd898721
    [started]=2019-05-24T11:14:22.920929Z
    [status]=error
reply['msg_id']=5c70e62f-47e6890f3d58a8363d91b19f
reply['msg_type']=execute_reply
reply['parent_header']=dict
    [date]=2019-05-24 11:14:22.919901+00:00
    [msg_id]=ae351f26-dfb9d90da7f2309e209b4008
    [msg_type]=execute_request
    [session]=8c36f839-60802fe3f46a518c70541a5e
    [username]=username
    [version]=5.3

----------------------------------------------------------------------
Ran 1 test in 5.353s

FAILED (errors=1)
----------------------------------------------------------------------
Ran 1 test in 0.102s

OK
